
Exception on /add [POST]
Traceback (most recent call last):
  File "/home/kishore/flask/gis/venv/local/lib/python2.7/site-packages/flask/app.py", line 1817, in wsgi_app
    response = self.full_dispatch_request()
  File "/home/kishore/flask/gis/venv/local/lib/python2.7/site-packages/flask/app.py", line 1477, in full_dispatch_request
    rv = self.handle_user_exception(e)
  File "/home/kishore/flask/gis/venv/local/lib/python2.7/site-packages/flask/app.py", line 1381, in handle_user_exception
    reraise(exc_type, exc_value, tb)
  File "/home/kishore/flask/gis/venv/local/lib/python2.7/site-packages/flask/app.py", line 1475, in full_dispatch_request
    rv = self.dispatch_request()
  File "/home/kishore/flask/gis/venv/local/lib/python2.7/site-packages/flask/app.py", line 1461, in dispatch_request
    return self.view_functions[rule.endpoint](**req.view_args)
  File "./gis.py", line 58, in add
    f.write(lon+'|'+str(lat)+'|'+date+'|'+details+'\n')
TypeError: unsupported operand type(s) for +: 'float' and 'str'
Exception on /view [GET]
Traceback (most recent call last):
  File "/home/kishore/flask/gis/venv/local/lib/python2.7/site-packages/flask/app.py", line 1817, in wsgi_app
    response = self.full_dispatch_request()
  File "/home/kishore/flask/gis/venv/local/lib/python2.7/site-packages/flask/app.py", line 1478, in full_dispatch_request
    response = self.make_response(rv)
  File "/home/kishore/flask/gis/venv/local/lib/python2.7/site-packages/flask/app.py", line 1566, in make_response
    raise ValueError('View function did not return a response')
ValueError: View function did not return a response
Exception on / [GET]
Traceback (most recent call last):
  File "/home/kishore/flask/gis/venv/local/lib/python2.7/site-packages/flask/app.py", line 1817, in wsgi_app
    response = self.full_dispatch_request()
  File "/home/kishore/flask/gis/venv/local/lib/python2.7/site-packages/flask/app.py", line 1477, in full_dispatch_request
    rv = self.handle_user_exception(e)
  File "/home/kishore/flask/gis/venv/local/lib/python2.7/site-packages/flask/app.py", line 1381, in handle_user_exception
    reraise(exc_type, exc_value, tb)
  File "/home/kishore/flask/gis/venv/local/lib/python2.7/site-packages/flask/app.py", line 1475, in full_dispatch_request
    rv = self.dispatch_request()
  File "/home/kishore/flask/gis/venv/local/lib/python2.7/site-packages/flask/app.py", line 1461, in dispatch_request
    return self.view_functions[rule.endpoint](**req.view_args)
  File "./gis.py", line 29, in index
    return render_template('gis.html')
  File "/home/kishore/flask/gis/venv/local/lib/python2.7/site-packages/flask/templating.py", line 127, in render_template
    return _render(ctx.app.jinja_env.get_or_select_template(template_name_or_list),
  File "/home/kishore/flask/gis/venv/local/lib/python2.7/site-packages/jinja2/environment.py", line 851, in get_or_select_template
    return self.get_template(template_name_or_list, parent, globals)
  File "/home/kishore/flask/gis/venv/local/lib/python2.7/site-packages/jinja2/environment.py", line 812, in get_template
    return self._load_template(name, self.make_globals(globals))
  File "/home/kishore/flask/gis/venv/local/lib/python2.7/site-packages/jinja2/environment.py", line 786, in _load_template
    template = self.loader.load(self, name, globals)
  File "/home/kishore/flask/gis/venv/local/lib/python2.7/site-packages/jinja2/loaders.py", line 125, in load
    code = environment.compile(source, name, filename)
  File "/home/kishore/flask/gis/venv/local/lib/python2.7/site-packages/jinja2/environment.py", line 565, in compile
    self.handle_exception(exc_info, source_hint=source_hint)
  File "/home/kishore/flask/gis/venv/local/lib/python2.7/site-packages/jinja2/environment.py", line 754, in handle_exception
    reraise(exc_type, exc_value, tb)
  File "/home/kishore/flask/gis/templates/gis.html", line 25, in template
    {% if {{ data }} %}
TemplateSyntaxError: expected token ':', got '}'
Exception on / [GET]
Traceback (most recent call last):
  File "/home/kishore/flask/gis/venv/local/lib/python2.7/site-packages/flask/app.py", line 1817, in wsgi_app
    response = self.full_dispatch_request()
  File "/home/kishore/flask/gis/venv/local/lib/python2.7/site-packages/flask/app.py", line 1477, in full_dispatch_request
    rv = self.handle_user_exception(e)
  File "/home/kishore/flask/gis/venv/local/lib/python2.7/site-packages/flask/app.py", line 1381, in handle_user_exception
    reraise(exc_type, exc_value, tb)
  File "/home/kishore/flask/gis/venv/local/lib/python2.7/site-packages/flask/app.py", line 1475, in full_dispatch_request
    rv = self.dispatch_request()
  File "/home/kishore/flask/gis/venv/local/lib/python2.7/site-packages/flask/app.py", line 1461, in dispatch_request
    return self.view_functions[rule.endpoint](**req.view_args)
  File "./gis.py", line 29, in index
    return render_template('gis.html', data=data)
  File "/home/kishore/flask/gis/venv/local/lib/python2.7/site-packages/flask/templating.py", line 127, in render_template
    return _render(ctx.app.jinja_env.get_or_select_template(template_name_or_list),
  File "/home/kishore/flask/gis/venv/local/lib/python2.7/site-packages/jinja2/environment.py", line 851, in get_or_select_template
    return self.get_template(template_name_or_list, parent, globals)
  File "/home/kishore/flask/gis/venv/local/lib/python2.7/site-packages/jinja2/environment.py", line 812, in get_template
    return self._load_template(name, self.make_globals(globals))
  File "/home/kishore/flask/gis/venv/local/lib/python2.7/site-packages/jinja2/environment.py", line 786, in _load_template
    template = self.loader.load(self, name, globals)
  File "/home/kishore/flask/gis/venv/local/lib/python2.7/site-packages/jinja2/loaders.py", line 125, in load
    code = environment.compile(source, name, filename)
  File "/home/kishore/flask/gis/venv/local/lib/python2.7/site-packages/jinja2/environment.py", line 565, in compile
    self.handle_exception(exc_info, source_hint=source_hint)
  File "/home/kishore/flask/gis/venv/local/lib/python2.7/site-packages/jinja2/environment.py", line 754, in handle_exception
    reraise(exc_type, exc_value, tb)
  File "/home/kishore/flask/gis/templates/gis.html", line 35, in template
    {% endif %}
TemplateSyntaxError: Encountered unknown tag 'endif'. You probably made a nesting mistake. Jinja is expecting this tag, but currently looking for 'endfor'. The innermost block that needs to be closed is 'for'.
Exception on / [GET]
Traceback (most recent call last):
  File "/home/kishore/flask/gis/venv/local/lib/python2.7/site-packages/flask/app.py", line 1817, in wsgi_app
    response = self.full_dispatch_request()
  File "/home/kishore/flask/gis/venv/local/lib/python2.7/site-packages/flask/app.py", line 1477, in full_dispatch_request
    rv = self.handle_user_exception(e)
  File "/home/kishore/flask/gis/venv/local/lib/python2.7/site-packages/flask/app.py", line 1381, in handle_user_exception
    reraise(exc_type, exc_value, tb)
  File "/home/kishore/flask/gis/venv/local/lib/python2.7/site-packages/flask/app.py", line 1475, in full_dispatch_request
    rv = self.dispatch_request()
  File "/home/kishore/flask/gis/venv/local/lib/python2.7/site-packages/flask/app.py", line 1461, in dispatch_request
    return self.view_functions[rule.endpoint](**req.view_args)
  File "./gis.py", line 29, in index
    return render_template('gis.html', data=data)
  File "/home/kishore/flask/gis/venv/local/lib/python2.7/site-packages/flask/templating.py", line 127, in render_template
    return _render(ctx.app.jinja_env.get_or_select_template(template_name_or_list),
  File "/home/kishore/flask/gis/venv/local/lib/python2.7/site-packages/jinja2/environment.py", line 851, in get_or_select_template
    return self.get_template(template_name_or_list, parent, globals)
  File "/home/kishore/flask/gis/venv/local/lib/python2.7/site-packages/jinja2/environment.py", line 812, in get_template
    return self._load_template(name, self.make_globals(globals))
  File "/home/kishore/flask/gis/venv/local/lib/python2.7/site-packages/jinja2/environment.py", line 786, in _load_template
    template = self.loader.load(self, name, globals)
  File "/home/kishore/flask/gis/venv/local/lib/python2.7/site-packages/jinja2/loaders.py", line 125, in load
    code = environment.compile(source, name, filename)
  File "/home/kishore/flask/gis/venv/local/lib/python2.7/site-packages/jinja2/environment.py", line 565, in compile
    self.handle_exception(exc_info, source_hint=source_hint)
  File "/home/kishore/flask/gis/venv/local/lib/python2.7/site-packages/jinja2/environment.py", line 754, in handle_exception
    reraise(exc_type, exc_value, tb)
  File "/home/kishore/flask/gis/templates/gis.html", line 31, in template
    details: '{{ point[3][0:len(point[3]-2] }}'});
TemplateSyntaxError: unexpected ']', expected ')'
Exception on / [GET]
Traceback (most recent call last):
  File "/home/kishore/flask/gis/venv/local/lib/python2.7/site-packages/flask/app.py", line 1817, in wsgi_app
    response = self.full_dispatch_request()
  File "/home/kishore/flask/gis/venv/local/lib/python2.7/site-packages/flask/app.py", line 1477, in full_dispatch_request
    rv = self.handle_user_exception(e)
  File "/home/kishore/flask/gis/venv/local/lib/python2.7/site-packages/flask/app.py", line 1381, in handle_user_exception
    reraise(exc_type, exc_value, tb)
  File "/home/kishore/flask/gis/venv/local/lib/python2.7/site-packages/flask/app.py", line 1475, in full_dispatch_request
    rv = self.dispatch_request()
  File "/home/kishore/flask/gis/venv/local/lib/python2.7/site-packages/flask/app.py", line 1461, in dispatch_request
    return self.view_functions[rule.endpoint](**req.view_args)
  File "./gis.py", line 29, in index
    return render_template('gis.html', data=data)
  File "/home/kishore/flask/gis/venv/local/lib/python2.7/site-packages/flask/templating.py", line 128, in render_template
    context, ctx.app)
  File "/home/kishore/flask/gis/venv/local/lib/python2.7/site-packages/flask/templating.py", line 110, in _render
    rv = template.render(context)
  File "/home/kishore/flask/gis/venv/local/lib/python2.7/site-packages/jinja2/environment.py", line 989, in render
    return self.environment.handle_exception(exc_info, True)
  File "/home/kishore/flask/gis/venv/local/lib/python2.7/site-packages/jinja2/environment.py", line 754, in handle_exception
    reraise(exc_type, exc_value, tb)
  File "/home/kishore/flask/gis/templates/gis.html", line 1, in top-level template code
    {% extends "base.html" %}
  File "/home/kishore/flask/gis/templates/base.html", line 39, in top-level template code
    {% block content %}{% endblock %}
  File "/home/kishore/flask/gis/templates/gis.html", line 31, in block "content"
    details: '{{ point[3][0:len(point[3])-2] }}'});
UndefinedError: 'len' is undefined
Exception on /kannolichira [GET]
Traceback (most recent call last):
  File "/home/kishore/flask/gis/venv/local/lib/python2.7/site-packages/flask/app.py", line 1817, in wsgi_app
    response = self.full_dispatch_request()
  File "/home/kishore/flask/gis/venv/local/lib/python2.7/site-packages/flask/app.py", line 1477, in full_dispatch_request
    rv = self.handle_user_exception(e)
  File "/home/kishore/flask/gis/venv/local/lib/python2.7/site-packages/flask/app.py", line 1381, in handle_user_exception
    reraise(exc_type, exc_value, tb)
  File "/home/kishore/flask/gis/venv/local/lib/python2.7/site-packages/flask/app.py", line 1475, in full_dispatch_request
    rv = self.dispatch_request()
  File "/home/kishore/flask/gis/venv/local/lib/python2.7/site-packages/flask/app.py", line 1461, in dispatch_request
    return self.view_functions[rule.endpoint](**req.view_args)
  File "./gis.py", line 81, in kannolichira
    return render_template('kannolichira.html', attr=attr)
  File "/home/kishore/flask/gis/venv/local/lib/python2.7/site-packages/flask/templating.py", line 128, in render_template
    context, ctx.app)
  File "/home/kishore/flask/gis/venv/local/lib/python2.7/site-packages/flask/templating.py", line 110, in _render
    rv = template.render(context)
  File "/home/kishore/flask/gis/venv/local/lib/python2.7/site-packages/jinja2/environment.py", line 989, in render
    return self.environment.handle_exception(exc_info, True)
  File "/home/kishore/flask/gis/venv/local/lib/python2.7/site-packages/jinja2/environment.py", line 754, in handle_exception
    reraise(exc_type, exc_value, tb)
  File "/home/kishore/flask/gis/templates/kannolichira.html", line 1, in top-level template code
    {% extends "base.html" %}
  File "/home/kishore/flask/gis/templates/base.html", line 39, in top-level template code
    {% block content %}{% endblock %}
  File "/home/kishore/flask/gis/templates/kannolichira.html", line 46, in block "content"
    FallowChunk: '{{ plot[17][0:len(plot[17])-1] }}'
UndefinedError: 'len' is undefined
Exception on /kannolichira [GET]
Traceback (most recent call last):
  File "/home/kishore/flask/gis/venv/local/lib/python2.7/site-packages/flask/app.py", line 1817, in wsgi_app
    response = self.full_dispatch_request()
  File "/home/kishore/flask/gis/venv/local/lib/python2.7/site-packages/flask/app.py", line 1477, in full_dispatch_request
    rv = self.handle_user_exception(e)
  File "/home/kishore/flask/gis/venv/local/lib/python2.7/site-packages/flask/app.py", line 1381, in handle_user_exception
    reraise(exc_type, exc_value, tb)
  File "/home/kishore/flask/gis/venv/local/lib/python2.7/site-packages/flask/app.py", line 1475, in full_dispatch_request
    rv = self.dispatch_request()
  File "/home/kishore/flask/gis/venv/local/lib/python2.7/site-packages/flask/app.py", line 1461, in dispatch_request
    return self.view_functions[rule.endpoint](**req.view_args)
  File "./gis.py", line 81, in kannolichira
    return render_template('kannolichira.html', attr=attr)
  File "/home/kishore/flask/gis/venv/local/lib/python2.7/site-packages/flask/templating.py", line 128, in render_template
    context, ctx.app)
  File "/home/kishore/flask/gis/venv/local/lib/python2.7/site-packages/flask/templating.py", line 110, in _render
    rv = template.render(context)
  File "/home/kishore/flask/gis/venv/local/lib/python2.7/site-packages/jinja2/environment.py", line 989, in render
    return self.environment.handle_exception(exc_info, True)
  File "/home/kishore/flask/gis/venv/local/lib/python2.7/site-packages/jinja2/environment.py", line 754, in handle_exception
    reraise(exc_type, exc_value, tb)
  File "/home/kishore/flask/gis/templates/kannolichira.html", line 1, in top-level template code
    {% extends "base.html" %}
  File "/home/kishore/flask/gis/templates/base.html", line 39, in top-level template code
    {% block content %}{% endblock %}
  File "/home/kishore/flask/gis/templates/kannolichira.html", line 46, in block "content"
    FallowChunk: '{{ plot[17][0:len(plot[17])-1] }}'
UndefinedError: 'len' is undefined
Exception on /kannolichira [GET]
Traceback (most recent call last):
  File "/home/kishore/flask/gis/venv/local/lib/python2.7/site-packages/flask/app.py", line 1817, in wsgi_app
    response = self.full_dispatch_request()
  File "/home/kishore/flask/gis/venv/local/lib/python2.7/site-packages/flask/app.py", line 1477, in full_dispatch_request
    rv = self.handle_user_exception(e)
  File "/home/kishore/flask/gis/venv/local/lib/python2.7/site-packages/flask/app.py", line 1381, in handle_user_exception
    reraise(exc_type, exc_value, tb)
  File "/home/kishore/flask/gis/venv/local/lib/python2.7/site-packages/flask/app.py", line 1475, in full_dispatch_request
    rv = self.dispatch_request()
  File "/home/kishore/flask/gis/venv/local/lib/python2.7/site-packages/flask/app.py", line 1461, in dispatch_request
    return self.view_functions[rule.endpoint](**req.view_args)
  File "./gis.py", line 81, in kannolichira
    return render_template('kannolichira.html', attr=attr)
  File "/home/kishore/flask/gis/venv/local/lib/python2.7/site-packages/flask/templating.py", line 128, in render_template
    context, ctx.app)
  File "/home/kishore/flask/gis/venv/local/lib/python2.7/site-packages/flask/templating.py", line 110, in _render
    rv = template.render(context)
  File "/home/kishore/flask/gis/venv/local/lib/python2.7/site-packages/jinja2/environment.py", line 989, in render
    return self.environment.handle_exception(exc_info, True)
  File "/home/kishore/flask/gis/venv/local/lib/python2.7/site-packages/jinja2/environment.py", line 754, in handle_exception
    reraise(exc_type, exc_value, tb)
  File "/home/kishore/flask/gis/templates/kannolichira.html", line 1, in top-level template code
    {% extends "base.html" %}
  File "/home/kishore/flask/gis/templates/base.html", line 39, in top-level template code
    {% block content %}{% endblock %}
  File "/home/kishore/flask/gis/templates/kannolichira.html", line 46, in block "content"
    FallowChunk: '{{ plot[17][0:len(plot[17])-1] }}'
UndefinedError: 'len' is undefined
Exception on /kannolichira [GET]
Traceback (most recent call last):
  File "/home/kishore/flask/gis/venv/local/lib/python2.7/site-packages/flask/app.py", line 1817, in wsgi_app
    response = self.full_dispatch_request()
  File "/home/kishore/flask/gis/venv/local/lib/python2.7/site-packages/flask/app.py", line 1477, in full_dispatch_request
    rv = self.handle_user_exception(e)
  File "/home/kishore/flask/gis/venv/local/lib/python2.7/site-packages/flask/app.py", line 1381, in handle_user_exception
    reraise(exc_type, exc_value, tb)
  File "/home/kishore/flask/gis/venv/local/lib/python2.7/site-packages/flask/app.py", line 1475, in full_dispatch_request
    rv = self.dispatch_request()
  File "/home/kishore/flask/gis/venv/local/lib/python2.7/site-packages/flask/app.py", line 1461, in dispatch_request
    return self.view_functions[rule.endpoint](**req.view_args)
  File "./gis.py", line 81, in kannolichira
    return render_template('kannolichira.html', attr=attr)
  File "/home/kishore/flask/gis/venv/local/lib/python2.7/site-packages/flask/templating.py", line 128, in render_template
    context, ctx.app)
  File "/home/kishore/flask/gis/venv/local/lib/python2.7/site-packages/flask/templating.py", line 110, in _render
    rv = template.render(context)
  File "/home/kishore/flask/gis/venv/local/lib/python2.7/site-packages/jinja2/environment.py", line 989, in render
    return self.environment.handle_exception(exc_info, True)
  File "/home/kishore/flask/gis/venv/local/lib/python2.7/site-packages/jinja2/environment.py", line 754, in handle_exception
    reraise(exc_type, exc_value, tb)
  File "/home/kishore/flask/gis/templates/kannolichira.html", line 1, in top-level template code
    {% extends "base.html" %}
  File "/home/kishore/flask/gis/templates/base.html", line 39, in top-level template code
    {% block content %}{% endblock %}
  File "/home/kishore/flask/gis/templates/kannolichira.html", line 46, in block "content"
    FallowChunk: '{{ plot[17][0:len(plot[17])-1] }}'});
UndefinedError: 'len' is undefined
Exception on /kannolichira [GET]
Traceback (most recent call last):
  File "/home/kishore/flask/gis/venv/local/lib/python2.7/site-packages/flask/app.py", line 1817, in wsgi_app
    response = self.full_dispatch_request()
  File "/home/kishore/flask/gis/venv/local/lib/python2.7/site-packages/flask/app.py", line 1477, in full_dispatch_request
    rv = self.handle_user_exception(e)
  File "/home/kishore/flask/gis/venv/local/lib/python2.7/site-packages/flask/app.py", line 1381, in handle_user_exception
    reraise(exc_type, exc_value, tb)
  File "/home/kishore/flask/gis/venv/local/lib/python2.7/site-packages/flask/app.py", line 1475, in full_dispatch_request
    rv = self.dispatch_request()
  File "/home/kishore/flask/gis/venv/local/lib/python2.7/site-packages/flask/app.py", line 1461, in dispatch_request
    return self.view_functions[rule.endpoint](**req.view_args)
  File "./gis.py", line 81, in kannolichira
    return render_template('kannolichira.html', attr=attr)
  File "/home/kishore/flask/gis/venv/local/lib/python2.7/site-packages/flask/templating.py", line 128, in render_template
    context, ctx.app)
  File "/home/kishore/flask/gis/venv/local/lib/python2.7/site-packages/flask/templating.py", line 110, in _render
    rv = template.render(context)
  File "/home/kishore/flask/gis/venv/local/lib/python2.7/site-packages/jinja2/environment.py", line 989, in render
    return self.environment.handle_exception(exc_info, True)
  File "/home/kishore/flask/gis/venv/local/lib/python2.7/site-packages/jinja2/environment.py", line 754, in handle_exception
    reraise(exc_type, exc_value, tb)
  File "/home/kishore/flask/gis/templates/kannolichira.html", line 1, in top-level template code
    {% extends "base.html" %}
  File "/home/kishore/flask/gis/templates/base.html", line 39, in top-level template code
    {% block content %}{% endblock %}
  File "/home/kishore/flask/gis/templates/kannolichira.html", line 46, in block "content"
    FallowChunk: '{{ plot[17][0:plot[17].count()-1] }}'});
TypeError: count() takes at least 1 argument (0 given)
Exception on /kannolichira [GET]
Traceback (most recent call last):
  File "/home/kishore/flask/gis/venv/local/lib/python2.7/site-packages/flask/app.py", line 1817, in wsgi_app
    response = self.full_dispatch_request()
  File "/home/kishore/flask/gis/venv/local/lib/python2.7/site-packages/flask/app.py", line 1477, in full_dispatch_request
    rv = self.handle_user_exception(e)
  File "/home/kishore/flask/gis/venv/local/lib/python2.7/site-packages/flask/app.py", line 1381, in handle_user_exception
    reraise(exc_type, exc_value, tb)
  File "/home/kishore/flask/gis/venv/local/lib/python2.7/site-packages/flask/app.py", line 1475, in full_dispatch_request
    rv = self.dispatch_request()
  File "/home/kishore/flask/gis/venv/local/lib/python2.7/site-packages/flask/app.py", line 1461, in dispatch_request
    return self.view_functions[rule.endpoint](**req.view_args)
  File "./gis.py", line 81, in kannolichira
    return render_template('kannolichira.html', attr=attr)
  File "/home/kishore/flask/gis/venv/local/lib/python2.7/site-packages/flask/templating.py", line 128, in render_template
    context, ctx.app)
  File "/home/kishore/flask/gis/venv/local/lib/python2.7/site-packages/flask/templating.py", line 110, in _render
    rv = template.render(context)
  File "/home/kishore/flask/gis/venv/local/lib/python2.7/site-packages/jinja2/environment.py", line 989, in render
    return self.environment.handle_exception(exc_info, True)
  File "/home/kishore/flask/gis/venv/local/lib/python2.7/site-packages/jinja2/environment.py", line 754, in handle_exception
    reraise(exc_type, exc_value, tb)
  File "/home/kishore/flask/gis/templates/kannolichira.html", line 1, in top-level template code
    {% extends "base.html" %}
  File "/home/kishore/flask/gis/templates/base.html", line 39, in top-level template code
    {% block content %}{% endblock %}
  File "/home/kishore/flask/gis/templates/kannolichira.html", line 46, in block "content"
    FallowChunk: '{{ plot[17][0:count(plot[17])-1] }}'});
UndefinedError: 'count' is undefined
Exception on /kannolichira [GET]
Traceback (most recent call last):
  File "/home/kishore/flask/gis/venv/local/lib/python2.7/site-packages/flask/app.py", line 1817, in wsgi_app
    response = self.full_dispatch_request()
  File "/home/kishore/flask/gis/venv/local/lib/python2.7/site-packages/flask/app.py", line 1477, in full_dispatch_request
    rv = self.handle_user_exception(e)
  File "/home/kishore/flask/gis/venv/local/lib/python2.7/site-packages/flask/app.py", line 1381, in handle_user_exception
    reraise(exc_type, exc_value, tb)
  File "/home/kishore/flask/gis/venv/local/lib/python2.7/site-packages/flask/app.py", line 1475, in full_dispatch_request
    rv = self.dispatch_request()
  File "/home/kishore/flask/gis/venv/local/lib/python2.7/site-packages/flask/app.py", line 1461, in dispatch_request
    return self.view_functions[rule.endpoint](**req.view_args)
  File "./gis.py", line 81, in kannolichira
    return render_template('kannolichira.html', attr=attr)
  File "/home/kishore/flask/gis/venv/local/lib/python2.7/site-packages/flask/templating.py", line 128, in render_template
    context, ctx.app)
  File "/home/kishore/flask/gis/venv/local/lib/python2.7/site-packages/flask/templating.py", line 110, in _render
    rv = template.render(context)
  File "/home/kishore/flask/gis/venv/local/lib/python2.7/site-packages/jinja2/environment.py", line 989, in render
    return self.environment.handle_exception(exc_info, True)
  File "/home/kishore/flask/gis/venv/local/lib/python2.7/site-packages/jinja2/environment.py", line 754, in handle_exception
    reraise(exc_type, exc_value, tb)
  File "/home/kishore/flask/gis/templates/kannolichira.html", line 1, in top-level template code
    {% extends "base.html" %}
  File "/home/kishore/flask/gis/templates/base.html", line 39, in top-level template code
    {% block content %}{% endblock %}
  File "/home/kishore/flask/gis/templates/kannolichira.html", line 46, in block "content"
    FallowChunk: '{{ plot[17][0:plot|count(plot[17])-1] }}'});
TypeError: len() takes exactly one argument (2 given)
Exception on /kannolichira [GET]
Traceback (most recent call last):
  File "/home/kishore/flask/gis/venv/local/lib/python2.7/site-packages/flask/app.py", line 1817, in wsgi_app
    response = self.full_dispatch_request()
  File "/home/kishore/flask/gis/venv/local/lib/python2.7/site-packages/flask/app.py", line 1477, in full_dispatch_request
    rv = self.handle_user_exception(e)
  File "/home/kishore/flask/gis/venv/local/lib/python2.7/site-packages/flask/app.py", line 1381, in handle_user_exception
    reraise(exc_type, exc_value, tb)
  File "/home/kishore/flask/gis/venv/local/lib/python2.7/site-packages/flask/app.py", line 1475, in full_dispatch_request
    rv = self.dispatch_request()
  File "/home/kishore/flask/gis/venv/local/lib/python2.7/site-packages/flask/app.py", line 1461, in dispatch_request
    return self.view_functions[rule.endpoint](**req.view_args)
  File "./gis.py", line 81, in kannolichira
    return render_template('kannolichira.html', attr=attr)
  File "/home/kishore/flask/gis/venv/local/lib/python2.7/site-packages/flask/templating.py", line 128, in render_template
    context, ctx.app)
  File "/home/kishore/flask/gis/venv/local/lib/python2.7/site-packages/flask/templating.py", line 110, in _render
    rv = template.render(context)
  File "/home/kishore/flask/gis/venv/local/lib/python2.7/site-packages/jinja2/environment.py", line 989, in render
    return self.environment.handle_exception(exc_info, True)
  File "/home/kishore/flask/gis/venv/local/lib/python2.7/site-packages/jinja2/environment.py", line 754, in handle_exception
    reraise(exc_type, exc_value, tb)
  File "/home/kishore/flask/gis/templates/kannolichira.html", line 1, in top-level template code
    {% extends "base.html" %}
  File "/home/kishore/flask/gis/templates/base.html", line 39, in top-level template code
    {% block content %}{% endblock %}
  File "/home/kishore/flask/gis/templates/kannolichira.html", line 46, in block "content"
    FallowChunk: '{{ plot[17][0:plot[17]|count()-1] }}'});
UndefinedError: list object has no element 17
Exception on /kannolichira [GET]
Traceback (most recent call last):
  File "/home/kishore/flask/gis/venv/local/lib/python2.7/site-packages/flask/app.py", line 1817, in wsgi_app
    response = self.full_dispatch_request()
  File "/home/kishore/flask/gis/venv/local/lib/python2.7/site-packages/flask/app.py", line 1477, in full_dispatch_request
    rv = self.handle_user_exception(e)
  File "/home/kishore/flask/gis/venv/local/lib/python2.7/site-packages/flask/app.py", line 1381, in handle_user_exception
    reraise(exc_type, exc_value, tb)
  File "/home/kishore/flask/gis/venv/local/lib/python2.7/site-packages/flask/app.py", line 1475, in full_dispatch_request
    rv = self.dispatch_request()
  File "/home/kishore/flask/gis/venv/local/lib/python2.7/site-packages/flask/app.py", line 1461, in dispatch_request
    return self.view_functions[rule.endpoint](**req.view_args)
  File "./gis.py", line 81, in kannolichira
    return render_template('kannolichira.html', attr=attr)
  File "/home/kishore/flask/gis/venv/local/lib/python2.7/site-packages/flask/templating.py", line 128, in render_template
    context, ctx.app)
  File "/home/kishore/flask/gis/venv/local/lib/python2.7/site-packages/flask/templating.py", line 110, in _render
    rv = template.render(context)
  File "/home/kishore/flask/gis/venv/local/lib/python2.7/site-packages/jinja2/environment.py", line 989, in render
    return self.environment.handle_exception(exc_info, True)
  File "/home/kishore/flask/gis/venv/local/lib/python2.7/site-packages/jinja2/environment.py", line 754, in handle_exception
    reraise(exc_type, exc_value, tb)
  File "/home/kishore/flask/gis/templates/kannolichira.html", line 1, in top-level template code
    {% extends "base.html" %}
  File "/home/kishore/flask/gis/templates/base.html", line 39, in top-level template code
    {% block content %}{% endblock %}
  File "/home/kishore/flask/gis/templates/kannolichira.html", line 46, in block "content"
    FallowChunk: '{{ plot[17][0:plot[17]|count()-1] }}'});
UndefinedError: list object has no element 17
Exception on /kannolichira [GET]
Traceback (most recent call last):
  File "/home/kishore/flask/gis/venv/local/lib/python2.7/site-packages/flask/app.py", line 1817, in wsgi_app
    response = self.full_dispatch_request()
  File "/home/kishore/flask/gis/venv/local/lib/python2.7/site-packages/flask/app.py", line 1477, in full_dispatch_request
    rv = self.handle_user_exception(e)
  File "/home/kishore/flask/gis/venv/local/lib/python2.7/site-packages/flask/app.py", line 1381, in handle_user_exception
    reraise(exc_type, exc_value, tb)
  File "/home/kishore/flask/gis/venv/local/lib/python2.7/site-packages/flask/app.py", line 1475, in full_dispatch_request
    rv = self.dispatch_request()
  File "/home/kishore/flask/gis/venv/local/lib/python2.7/site-packages/flask/app.py", line 1461, in dispatch_request
    return self.view_functions[rule.endpoint](**req.view_args)
  File "./gis.py", line 99, in kannolichira
    return render_template('kannolichira.html', attr=attr)
  File "/home/kishore/flask/gis/venv/local/lib/python2.7/site-packages/flask/templating.py", line 127, in render_template
    return _render(ctx.app.jinja_env.get_or_select_template(template_name_or_list),
  File "/home/kishore/flask/gis/venv/local/lib/python2.7/site-packages/jinja2/environment.py", line 851, in get_or_select_template
    return self.get_template(template_name_or_list, parent, globals)
  File "/home/kishore/flask/gis/venv/local/lib/python2.7/site-packages/jinja2/environment.py", line 812, in get_template
    return self._load_template(name, self.make_globals(globals))
  File "/home/kishore/flask/gis/venv/local/lib/python2.7/site-packages/jinja2/environment.py", line 786, in _load_template
    template = self.loader.load(self, name, globals)
  File "/home/kishore/flask/gis/venv/local/lib/python2.7/site-packages/jinja2/loaders.py", line 125, in load
    code = environment.compile(source, name, filename)
  File "/home/kishore/flask/gis/venv/local/lib/python2.7/site-packages/jinja2/environment.py", line 565, in compile
    self.handle_exception(exc_info, source_hint=source_hint)
  File "/home/kishore/flask/gis/venv/local/lib/python2.7/site-packages/jinja2/environment.py", line 754, in handle_exception
    reraise(exc_type, exc_value, tb)
  File "/home/kishore/flask/gis/templates/kannolichira.html", line 29, in template
    plots.push({{ plot|json }});
TemplateAssertionError: no filter named 'json'
